Workbook

Sheet 안내
A1: 고인돌의 별자리 — 데이터 수정용 엑셀
A3: 이 파일을 고쳐서 다시 보내주시면 웹페이지(HTML)를 새로 만들어 드립니다.
A5: 시트 설명
A6: 노드: 화면의 별 하나가 한 줄입니다. 이름, 분류, 설명을 자유롭게 고치고, 새 별은 맨 아래 줄에 추가합니다.
A7: 연결: 두 별을 잇는 선입니다. 한 줄이 선 하나이고, 시작id와 끝id는 노드 시트의 id를 고르면 됩니다.
A8: 분류: 별의 그룹과 색입니다. 새 그룹을 만들면 노드 시트의 분류 칸에서 고를 수 있습니다.
A10: 수정 규칙
A11: 1. id는 노드마다 달라야 하고 한 번 쓰면 바꾸지 않는 것이 안전합니다. 영문·숫자로 쓰세요. (예: b8)
A12: 2. 별을 지우려면 노드 시트의 줄과, 연결 시트에서 그 id가 들어간 줄을 함께 지웁니다.
A13: 3. 출처·메모 칸은 연구용 메모입니다. 지금 화면에는 나오지 않으며, 화면에 보이길 원하시면 알려주세요.
A14: 4. 철학(p) 분류의 내용은 자료 원문이 아니라 연구 방향을 정리한 해석 초안입니다.
A16: 예시 (새 별 추가)
... A28: C28의 위치값 맨 앞에 있던 쉼표를 지웠습니다.

Sheet 노드
A1: id | B1: 이름 | C1: 분류(코드) | D1: 설명 | E1: 사진 | F1: 기억의 역할 | G1: 기억의 눈 (초안)
A2: a1 | B2: 일제시대의 청동기 | C2: a | D2: 청동기시대 개념이 없던 시기입니다. 김해패총 조사에서 석기와 청동기가 함께 나오자 금석병용기라는 모호한 개념이 세워졌습니다. | F2: 기능기억 | G2: 당시 학계가 만든 개념이 청동기를 이해하는 틀이 되었습니다. 어떤 과거를 어떻게 정리할지 정한 학문의 모습입니다.
A3: a2 | B3: 금석병용기 폐기 | C3: a | D3: 1950년대 북한에서 무문토기 출토 유적이 조사되며 부정되었고, 남한에서는 1960년대에 폐기되어 청동기시대 개념이 자리 잡았습니다. | F3: 저장기억 | G3: 새 조사 자료가 쌓이며 기존 개념이 폐기되었습니다. 저장된 자료가 기억의 틀을 바로잡은 사례입니다.
A4: a3 | B4: 1960~70년대 연대 논쟁 | C4: a | D4: 도유호, 김정학, 김원룡, 윤무병, 김정배 등이 서로 다른 상한과 하한을 제시했습니다. | F4: 저장기억 | G4: 저장된 자료는 하나인데 학설은 여러 갈래입니다. 자료가 있어도 어떻게 읽을지는 정해져 있지 않습니다.
A5: a4 | B5: 1980년대 연구 | C5: a | D5: 연대관이 평행선을 달리는 가운데, 최성락은 방사성탄소연대를 재계산해 기원전 1300~1200년을 제시했고 이형구는 발해만 지구에서 기원을 찾았습니다. | F5: 저장기억
A6: a5 | B6: 연대의 세 갈래 | C6: a | D6: 청동기 개시를 기원전 1000년경, 7~8세기, 5세기 전후로 보는 세 견해가 맞섭니다. 무문토기 단계를 보는 시각, 담당 종족, 유입 경로에 따라 갈립니다. | F6: 기능기억 | G6: 담당 종족과 유입 경로를 어떻게 보느냐에 따라 연대가 갈립니다. 집단이 어떤 기원을 기억하고 싶은지가 해석에 스며들 수 있는지 물어볼 수 있습니다.
A7: a6 | B7: 청동기 기원 경로 | C7: a | D7: 시베리아 카라수크·타가르 계통, 요령과 중국(화중, 은허) 계통 등의 가설이 맞섭니다. 요령식동검과 세형동검을 다른 문화로 볼지도 쟁점입니다. | F7: 기능기억 | G7: 기원을 어디서 찾느냐는 집단이 자신을 어떻게 기억하느냐와 얽히는 물음입니다.
A8: a7 | B8: 청동기 제작 집단 | C8: a | D8: 청동기 제작 집단이나 공방의 발견이 실체 파악에 필요하다고 지적합니다. 요령과 시베리아 유적까지 직접 발굴해야 한다고 봅니다. | F8: 저장기억 | G8: 아직 발견되지 않은 자료가 있다는 것은 저장기억에 빈 곳이 있다는 뜻입니다.
A9: a8 | B9: 사회 변화 | C9: a | D9: 농경이 발전하면서 생산물이 늘어나고, 이를 둘러싼 사회적 관계도 변화하였습니다. 청동기시대의 무덤과 부장품은 당시 사회의 차이를 살펴볼 수 있는 자료로 연구됩니다. | F9: 저장기억
A10: a9 | B10: 의례 | C10: a | D10: 청동기시대 유적에서는 무덤뿐 아니라 의례와 관련된 공간과 유물이 확인됩니다. 고인돌 역시 무덤과 장송의례를 이해하는 중요한 자료입니다. | F10: 기능기억 | G10: 의례는 기억을 되풀이해 살아 있게 하는 대표적인 방식으로 논의됩니다.
A11: b1 | B11: 기원과 전파 | C11: b | D11: 시베리아 카라수크 돌널무덤 계통의 북방설, 동남아시아에서 왔다는 남방설, 한반도에서 독립적으로 생겼다는 자생설이 있습니다. | F11: 저장기억
A12: b2 | B12: 바둑판식(남방식) 고인돌 | C12: b | D12: 판석, 깬돌(割石), 냇돌 등을 사용하여 지하에 돌방을 만들고, 뚜껑돌과 돌방 사이에 3∼4개 또는 그 이상의 받침돌(支石)을 괸 형태의 고인돌입니다. 주로 전라도 · 경상도 등 한강 이남지역에 분포합니다. | F12: 매체
A13: b3 | B13: 개석식(지상석곽식 ) | C13: b | D13: 뚜껑돌과 지하 돌방 사이에 받침돌 없이 뚜껑돌이 직접 돌방을 덮고 있는 형식의 고인돌입니다. ＜무지석식(無支石式)＞ 또는 ＜놓인 형 고인돌＞이라고도 하는데, 남방식 고인돌에 포함시키기도 합니다. 개석식 고인돌의 또 다른 특징은 돌방 주위 사면에 얇고 납작한 돌을 평탄하게 깔아 놓은 적석시설(積石施設)입니다. 국토 전역에 걸쳐 분포하고 있으며 숫자상으로도 가장 많습니다. | F13: 매체
A14: b4 | B14: 돌덧널(석관묘) | C14: b | D14: 땅속에 깊이 움을 파고 깬돌이나 모난돌을 사용하거나 또는 깬돌과 판돌로 관을 싸는 덧널을 직사각형으로 쌓아 만든 무덤형태 입니다. | F14: 매체
A15: b5 | B15: 돌널(석곽) | C15: b | D15: 돌널무덤은 고인돌, 돌뚜껑움무덤, 독널무덤과 더불어 한국 청동기시대의 대표적인 무덤 양식 중 하나입니다. 돌널무덤은 지하에 묘광을 파고 판돌이나 깬돌 등으로 장방형의 매장주체부를 만들고 그 위에 1매 이상의 뚜껑돌을 덮은 무덤 양식을 의미합니다. | F15: 매체
A16: b6 | B16: 형식 분류 | C16: b | D16: 북방식(탁자식), 남방식(기반식), 개석식으로 나눕니다. 북방식은 주로 한강 이북, 남방식은 한강 이남, 개석식은 한반도 전역에 분포합니다. | F16: 저장기억 | G16: 분류는 흩어진 돌에 이름을 붙여 보관하는 저장의 방식입니다.
A17: b7 | B17: 형식의 변천 | C17: b | D17: 북방식이 먼저 나타나 남으로 퍼졌다는 전통적 견해, 남방식을 말기 형식으로 보는 설, 개석식을 원초형으로 보는 설이 있습니다. 북한은 침촌형에서 오덕형으로 발전했다고 봅니다. | F17: 저장기억
A18: b8 | B18: 세계의 고인돌 | C18: b | D18: 유럽에서는 보정된 방사성탄소연대로 기원전 4000년대까지 오른다고 보고됩니다. 프랑스, 영국, 중국, 일본, 인도, 러시아 사례를 함께 다룹니다. | F18: 매체 | G18: 돌에 기억을 맡기는 방식이 한 곳의 일이 아니었음을 보여 줍니다.
A19: b9 | B19: 주요 유적 | C19: b | D19: 강화, 고창, 부안, 화순 등 대표 유적을 개별 장으로 다룹니다. 고창 도산리는 남쪽에서 드물게 북방식이 발견되는 사례로 언급됩니다. | F19: 기능기억 | G19: 일부 유적은 보존과 전시를 거치며 기억의 무대 위로 올라옵니다.
A20: b10 | B20: 사회복원 | C20: b | D20: 지석묘 사회 연구의 이론과 방법, 형식 분류, 계급의 발생을 다룹니다. 뚜껑돌의 채석과 운반은 인구, 경제, 정치와 얽힌 문제로 봅니다. | F20: 저장기억 | G20: 고고학은 돌에서 사회를 다시 짜 맞춥니다. 복원은 기억이 아니라 재구성이라는 점을 짚어 볼 수 있습니다.
A21: b11 | B21: 보존과 활용 | C21: b | D21: 고고문화재의 효율적 관리와 지석묘의 보존 관리, 활용 방안을 다룹니다. | F21: 기능기억 | G21: 무엇을 지키고 어떻게 보여 줄지 정하는 일은 기억을 선택하는 일입니다.
A22: b12 | B22: 탁자식 고인돌 | C22: b | D22: 탁자식고인돌은 넓은 판석으로 축조한 무덤방이 지상에 노출되어 있는 형식으로, 판석 4매 혹은 6매 이내로 짜 맞춘 석실 위에 납작한 덮개돌이 올려진 것이다. 주로 한강 이북에서 중국 요령지방에 집중 분포되어 있기 때문에 북방식(北方式)으로 불리기도 한다. 북한에서는 오덕형(五德形)이라 하고, 중국에서는 집모양인 것에서 석붕(石棚)이라고 한다. | F22: 매체
A23: b13 | B23: 기반식 고인돌 | C23: b | D23: 기반식고인돌은 남방식고인돌 또는 바둑판식고인돌이라고도 불리며, 주로 전라도와 경상도 등 한강 이남 지역에 분포하고 있습니다. 판돌(板石), 깬돌(割石), 냇돌(川石) 등을 이용해 지하에 무덤칸을 만든 뒤, 그 위에 덮개돌(上石)을 놓고 무덤칸과 덮개돌 사이에 3개에서 4개 이상(또는 그 이상의) 고임돌(支石)을 배치하는 형태입니다. | F23: 매체
A24: d0 | B24: 거석문화 | C24: d | D24: 고인돌을 비롯한 거석문화의 분포는 북유럽, 서유럽, 지중해 연안지역, 인도, 동남아시아, 동북아시아 지역으로 유라시아 대륙을 에워싸고 있는 거의 세계적인 분포를 보이고 있다. | F24: 매체 | G24: 돌에 기억을 맡기는 방식이 한 지역을 넘어 공유되었음을 보여 줍니다.
A25: d1 | B25: 열석 | C25: d | D25: 열석은 선돌이 한 줄이나 여러 줄이 평행으로 세워진 석열(石列) 형태이다. 유럽 특히 프랑스 브레타뉴지방의 열석이 대표적이지만 우리나라에서는 발견되지 않고 있다. 이런 열석은 제사와 관련된 것으로 보는 견해와 하지나 동지와 관련된 의례행위, 하루의 시간이나 계절을 추정하는 기능으로 보기도 한다. | F25: 매체
A26: d2 | B26: 환상열석 | C26: d | D26: 환상열석은 선돌을 원형으로 배열한 형태로, 한 열 또는 이중으로 배열한 것이 있다. 대표적인 것이 영국의 스톤헨지(Stone Henge)로 여기에 사용된 청석은 210km 떨어진 곳에서 이동해 온 거석으로 30개 정도의 돌을 원형으로 세우고 그 위를 연결시킨 것이다. 이러한 환상열석은 장례와 관련되는 특수 의식 장소로 보는 견해와 하지 때 일출과 관련하여 천체관측의 기능으로 보는 견해가 있다. | F26: 매체
A27: d3 | B27: 선돌 | C27: d | D27: 선돌은 고인돌과 함께 거석문화를 대표하는 것으로 하나의 돌을 수직으로 세워 놓은 형태를 말한다. 선돌의 기원은 일반적으로 생산과 풍요를 기원하는 남근(男根)숭배와 관련된 것으로 보고 있다. | F27: 매체
A28: d4 | B28: 석상 | C28: d | D28: 석상은 돌에 사람의 얼굴 등 형상을 묘사하여 세워놓은 것을 말한다. 우리나라에 흔한 벅수(장승)나 제주도에 많은 돌 하루방, 묘 앞에 세워진 문· 무인석 같은 형태를 말한다. 이 석상은 여러 나라에서 발견되지만 남태평양에 있는 조그마한 이스터섬의 석상이 대표적이다. | F28: 매체
A29: dol | B29: 고인돌(지석묘) | C29: c | D29: 선사시대 돌무덤의 한 유형으로 거석문화에 속하며, 무덤의 기능을 한 것으로 인식됩니다. | F29: 매체 | G29: 문자 없는 사회가 남긴 거대한 기념물입니다. 무엇을 기억하려 했는지는 전해지지 않고, 기억하려 한 행위만 돌로 남았습니다.
A30: k1 | B30: 금강 유역 고인돌 | C30: k | D30: 대상 유물이 출토된 지역인 금강 유역의 고인돌을 알아봅니다. | F30: 매체 | G30: 한 유역에 모인 돌들은 같은 기억의 공간이 남긴 흔적으로 읽어 볼 수 있습니다.
A31: k10 | B31: 군산 나포리 지석묘군 | C31: k | D31: 나장초등학교 북동쪽 산구릉에 4기의 지석묘가 자리하고 있다. 지석은 확인되지 않으며, 개석은 남북으로 장축방향을 두고 있다. 지석이 있는 것도 있으며, 선돌로 보이는 것도 1기 있다. | F31: 매체
A32: k11 | B32: 군산 선제리 지석묘군 | C32: k | D32: 옥구교회에서 서쪽으로 약 250m 쯤 떨어진 지역의 구릉 위에 2기의 지석묘가 자리하고 있다. 이 지역은 월명산에서 길게 뻗어 내린 능선이 끝나면서 형성된 얕은 구릉지대로 대부분의 지역이 오래 전에 밭으로 개간된 상태이다. 1호 지석묘는 장축 305cm, 단축 246cm, 두께는 115cm 로 지석은 보이지 않고 남북으로 장축방향을 두고 있다. 이 지석묘는 개석의 일부가 땅 속에 묻혀 있지만 보존상태는 비교적 양호한 편이다. 이 지석묘에서 동쪽으로 5m쯤 떨어진 지점에 자리한 2호 지석묘는 최근에 개석이 심하게 파손되어 일부만 남아있다. | F32: 매체
A33: k12 | B33: 군산 여방리 지석묘군 B | C33: k | D33: 수심마을은 오성산(227m) 동쪽 기슭의 하단부에 자리하고 있는데, 이 마을의 동쪽에는 오성산에서 동남쪽으로 뻗어 내린 능선이 마을의 동쪽 지역을 감싸고 있다. 능선은 동쪽 기슭의 중앙에서 시작해 남전마을까지 계속되고 있는데, 지석묘는 수심마을에서 북동쪽으로 300m 남짓 떨어진 능선의 정상부에 자리하고 있다. 지석묘는 동남쪽으로 뻗어 내린 주능선의 정상부에 1기가 자리하고 있으며, 그 주변지역에는 개석으로 추정되는 2기의 판석형 석재가 북쪽 기슭을 따라 기울어진 상태로 놓여 있다. 판석형 개석은 남쪽으로 약간 기울어진 상태로 능선과 평행되게 남북으로 장축방향을 두고 있으며, 그 상면에는 많은 수의 성혈이 선명하게 남아있다. 이 지석묘는 3개의 지석이 개석을 받치고 있는 지석식으로, 그 규모는 남북길이 406cm, 동서폭 385cm, 두께 96cm이다. 이것은 지금까지 군산을 비롯하여 금강 하류지역에서 조사된 지석묘 중 최대규모이고, 그 보존상태가 매우 양호하여 장차 이 지역의 선사시대를 연구하는데 있어 값진 자료로 주목을 받고 있다. | F33: 매체
A34: k13 | B34: 논산 신기리 고암 지석묘 | C34: k | D34: 1949년부터 그 존재가 알려졌으며 1965년 국립중앙박물관에서 2기, 1973년 국립부여 박물관에서 1기를 발굴 조사하였다. 장선천의 천변에 지석묘 20여기가 남아 있다. 지석묘는 석실을 판석으로 지상에 세우고 그 위에 상석을 올린 탁자식과 하부구조가 지하에 있고 지상에 상석을 관의 뚜껑처럼 덮은 개석식으로 구분된다. 1호와 2호는 탁자식 지석묘이며, 3호 지석묘는 개석식 지석묘이다. | F34: 매체
A35: k14 | B35: 칠성당지석묘군 | C35: k | D35: 대전 유성구 교촌동의 마을 뒷산에 있는 남방식 고인돌로 모두 7기가 밀집되어 있다. 이 고인돌은 작은 것은 길이 1m, 큰 것은 약 7m로 다양하며, 일부는 받침돌이 지상에 노출되어 있다. 옛날에 아기를 낳지 못한 한 여인이 북두칠성 모양을 한 7개의 바위들을 발견하고 백일 동안 하루도 빠지지 않고 아들 낳기를 빌어 얼마 후에 아들을 낳아 소원을 성취했다는 내용의 전설이 전해지고 있다. 이때부터 사람들은 바위들이 대단한 영험을 지니고 있다고 믿게 되었고, 칠성바위를 대상으로 제사를 지내며 마을의 무사태평과 안녕을 기원했다고 한다. | F35: 매체
A36: k2 | B36: 금산 천내리 고인돌 | C36: k | D36: 모두 12기의 고인돌로 천내강을 굽어보고 있다. 마을에서는 이 고인돌들을 팔선바위라 하여 신성시하고 함부로 건드리지 않는다. 주변 입지는 용화리에서 흘러온 금강의 물줄기가 이 구릉을 S자 형태로 휘어돌아 충청북도 영동 쪽으로 빠져나가고 금산읍에서 나오는 봉황천과 천내천이 합류하는 곳이다. 천내리 고인돌의 형태는 개석식 또는 바둑판식이며, 개석의 형태는 사각형 또는 부정형이며 200m 안팎의 크기이다. 주민들에 의하면 예전에 고인돌이 있는 곳에서 돌칼, 돌화살촉과 붉은 토기 등이 출토되었다고 한다. | F36: 매체
A37: k3 | B37: 비래동고인돌 | C37: k | D37: 비래동 비래골 마을회관 앞 논에 고인돌 2기가 있고, 맞은편 구릉 정상부에 1기의 고인돌이 있다. 1호 고인돌은 덮개돌의 절반이 마치 입석처럼 세워져 있는데, 1963년 새마을 운동 당시 동네 주민들이 덮개돌을 쪼개 표면에 새마을기를 그려 넣었다고 한다. 2호 고인돌은 1호 고인돌에서 동쪽으로 약 5m 떨어진 곳에 있으며, 덮개돌의 규모는 길이 2.9m, 너비 2.6m이고 표면에는 알구멍<성혈(性穴):풍년을 기원하거나 자식낳기를 기원하는 의미에서 만든 구멍> 16개가 불규칙적으로 표현되었다. | F37: 매체
A38: k4 | B38: 충주 조동리 고인돌 | C38: k | D38: 조동리 지석묘는 바둑판식 고인돌로서 3층 구조의 특이한 외부구조를 갖추고 있고, 보존상태도 매우 양호하며, 청동기시대의 묘제연구에 중요한 학술 자료가 된다. 특히, 조동리 선사시대(신석기∼청동기) 생활유적과 인접하고 있어 중원지방의 청동기시대 생활문화상을 연구하는데 매우 중요한 유적이다. | F38: 매체
A39: k5 | B39: 충주 신청리 고인돌 | C39: k | D39: 이 지석묘는 충주시 신니면 신청리 502에 위치한 지석묘이다. 개석식 지석묘로 본래의 모습을 잘 유지하고 있으며 덮개돌 윗면에 크고 작은 굼<性穴>이 141개 분포하고 있어 선사시대 거석문화 연구, 특히 매장행위와 관련된 중요한 자료이다. | F39: 매체
A40: k6 | B40: 옥천 석탄리 고인돌 | C40: k | D40: 옥천지석묘는 탁자식 고인돌로, 4면에 널돌을 세우고 그 위로 길고 평평한 덮개돌을 얹은 모습이었는데, 현재는 앞뒷면 널돌은 사라지고 양쪽면에만 널돌이 남아있다. 이곳에서 발견된 유물은 갈돌대, 돌쩌귀, 돌칼, 돌화살촉, 그물추, 구멍쪼으개, 여성을 나타낸 얼굴조각, 토기 등 이다. 주로 식생활에 관련된 유물이 많아 묻힌 사람은 여자였을 것으로 판단된다. | F40: 매체
...

Sheet 연결
A1: 시작id | B1: 끝id | C1: 시작 이름(참고) | D1: 끝 이름(참고) | E1: 관계 유형 | F1: 이유 (한 줄)
A2: dol | B2: b1 | C2: {=IFERROR(INDEX('노드'!$B$2:$B$520,MATCH(A2,'노드'!$A$2:$A$520,0)),"")} | D2: {=IFERROR(INDEX('노드'!$B$2:$B$520,MATCH(B2,'노드'!$A$2:$A$520,0)),"")} | E2: 기원 | F2: 고인돌이 어디서 왔는지를 다룬 학설입니다.
A3: dol | B3: b2 | C3: {=IFERROR(INDEX('노드'!$B$2:$B$520,MATCH(A3,'노드'!$A$2:$A$520,0)),"")} | D3: {=IFERROR(INDEX('노드'!$B$2:$B$520,MATCH(B3,'노드'!$A$2:$A$520,0)),"")}
A4: dol | B4: b4 | C4: {=IFERROR(INDEX('노드'!$B$2:$B$520,MATCH(A4,'노드'!$A$2:$A$520,0)),"")} | D4: {=IFERROR(INDEX('노드'!$B$2:$B$520,MATCH(B4,'노드'!$A$2:$A$520,0)),"")}
A5: dol | B5: b5 | C5: {=IFERROR(INDEX('노드'!$B$2:$B$520,MATCH(A5,'노드'!$A$2:$A$520,0)),"")} | D5: {=IFERROR(INDEX('노드'!$B$2:$B$520,MATCH(B5,'노드'!$A$2:$A$520,0)),"")}
A6: dol | B6: b6 | C6: {=IFERROR(INDEX('노드'!$B$2:$B$520,MATCH(A6,'노드'!$A$2:$A$520,0)),"")} | D6: {=IFERROR(INDEX('노드'!$B$2:$B$520,MATCH(B6,'노드'!$A$2:$A$520,0)),"")}
A7: dol | B7: b7 | C7: {=IFERROR(INDEX('노드'!$B$2:$B$520,MATCH(A7,'노드'!$A$2:$A$520,0)),"")} | D7: {=IFERROR(INDEX('노드'!$B$2:$B$520,MATCH(B7,'노드'!$A$2:$A$520,0)),"")}
A8: dol | B8: a5 | C8: {=IFERROR(INDEX('노드'!$B$2:$B$520,MATCH(A8,'노드'!$A$2:$A$520,0)),"")} | D8: {=IFERROR(INDEX('노드'!$B$2:$B$520,MATCH(B8,'노드'!$A$2:$A$520,0)),"")} | E8: 논쟁 | F8: 고인돌이 속한 청동기시대의 시작 연대를 둘러싼 세 견해입니다.
A9: dol | B9: a6 | C9: {=IFERROR(INDEX('노드'!$B$2:$B$520,MATCH(A9,'노드'!$A$2:$A$520,0)),"")} | D9: {=IFERROR(INDEX('노드'!$B$2:$B$520,MATCH(B9,'노드'!$A$2:$A$520,0)),"")} | E9: 기원 | F9: 고인돌과 함께 논의되는 청동기 문화의 기원 가설입니다.
A10: dol | B10: p2 | C10: {=IFERROR(INDEX('노드'!$B$2:$B$520,MATCH(A10,'노드'!$A$2:$A$520,0)),"")} | D10: {=IFERROR(INDEX('노드'!$B$2:$B$520,MATCH(B10,'노드'!$A$2:$A$520,0)),"")} | E10: 지각 | F10: 관람자가 돌을 처음 마주치는 몸의 경험입니다.
A11: dol | B11: p8 | C11: {=IFERROR(INDEX('노드'!$B$2:$B$520,MATCH(A11,'노드'!$A$2:$A$520,0)),"")} | D11: {=IFERROR(INDEX('노드'!$B$2:$B$520,MATCH(B11,'노드'!$A$2:$A$520,0)),"")} | E11: 단절 | F11: 축조자와 오늘의 관람자 사이에 전승이 끊겨 있습니다.
A12: a1 | B12: a2 | C12: {=IFERROR(INDEX('노드'!$B$2:$B$520,MATCH(A12,'노드'!$A$2:$A$520,0)),"")} | D12: {=IFERROR(INDEX('노드'!$B$2:$B$520,MATCH(B12,'노드'!$A$2:$A$520,0)),"")} | E12: 변화 | F12: 개념이 폐기되며 청동기시대 개념이 자리 잡았습니다.
A13: a2 | B13: a3 | C13: {=IFERROR(INDEX('노드'!$B$2:$B$520,MATCH(A13,'노드'!$A$2:$A$520,0)),"")} | D13: {=IFERROR(INDEX('노드'!$B$2:$B$520,MATCH(B13,'노드'!$A$2:$A$520,0)),"")} | E13: 이어짐 | F13: 개념 정리 뒤 연대 논쟁이 본격화됩니다.
A14: a3 | B14: a4 | C14: {=IFERROR(INDEX('노드'!$B$2:$B$520,MATCH(A14,'노드'!$A$2:$A$520,0)),"")} | D14: {=IFERROR(INDEX('노드'!$B$2:$B$520,MATCH(B14,'노드'!$A$2:$A$520,0)),"")} | E14: 이어짐 | F14: 1970년대 논쟁이 1980년대 연구로 이어집니다.
A15: a3 | B15: a5 | C15: {=IFERROR(INDEX('노드'!$B$2:$B$520,MATCH(A15,'노드'!$A$2:$A$520,0)),"")} | D15: {=IFERROR(INDEX('노드'!$B$2:$B$520,MATCH(B15,'노드'!$A$2:$A$520,0)),"")} | E15: 논쟁 | F15: 연대 논쟁이 세 갈래의 견해로 정리됩니다.
A16: a4 | B16: a5 | C16: {=IFERROR(INDEX('노드'!$B$2:$B$520,MATCH(A16,'노드'!$A$2:$A$520,0)),"")} | D16: {=IFERROR(INDEX('노드'!$B$2:$B$520,MATCH(B16,'노드'!$A$2:$A$520,0)),"")} | E16: 논쟁 | F16: 1980년대 연구도 같은 쟁점 위에서 움직입니다.
A17: a5 | B17: a6 | C17: {=IFERROR(INDEX('노드'!$B$2:$B$520,MATCH(A17,'노드'!$A$2:$A$520,0)),"")} | D17: {=IFERROR(INDEX('노드'!$B$2:$B$520,MATCH(B17,'노드'!$A$2:$A$520,0)),"")} | E17: 쟁점 | F17: 연대는 기원 경로를 어떻게 보느냐와 맞물립니다.
A18: a6 | B18: a7 | C18: {=IFERROR(INDEX('노드'!$B$2:$B$520,MATCH(A18,'노드'!$A$2:$A$520,0)),"")} | D18: {=IFERROR(INDEX('노드'!$B$2:$B$520,MATCH(B18,'노드'!$A$2:$A$520,0)),"")} | E18: 과제 | F18: 기원을 가리려면 제작 집단의 발견이 필요하다는 지적입니다.
A19: a6 | B19: b1 | C19: {=IFERROR(INDEX('노드'!$B$2:$B$520,MATCH(A19,'노드'!$A$2:$A$520,0)),"")} | D19: {=IFERROR(INDEX('노드'!$B$2:$B$520,MATCH(B19,'노드'!$A$2:$A$520,0)),"")} | E19: 비교 | F19: 청동기 기원 경로와 고인돌 기원설을 나란히 비교합니다.
A20: b1 | B20: b3 | C20: {=IFERROR(INDEX('노드'!$B$2:$B$520,MATCH(A20,'노드'!$A$2:$A$520,0)),"")} | D20: {=IFERROR(INDEX('노드'!$B$2:$B$520,MATCH(B20,'노드'!$A$2:$A$520,0)),"")}
A21: b2 | B21: b3 | C21: {=IFERROR(INDEX('노드'!$B$2:$B$520,MATCH(A21,'노드'!$A$2:$A$520,0)),"")} | D21: {=IFERROR(INDEX('노드'!$B$2:$B$520,MATCH(B21,'노드'!$A$2:$A$520,0)),"")}
A22: b2 | B22: b5 | C22: {=IFERROR(INDEX('노드'!$B$2:$B$520,MATCH(A22,'노드'!$A$2:$A$520,0)),"")} | D22: {=IFERROR(INDEX('노드'!$B$2:$B$520,MATCH(B22,'노드'!$A$2:$A$520,0)),"")}
A23: b5 | B23: b6 | C23: {=IFERROR(INDEX('노드'!$B$2:$B$520,MATCH(A23,'노드'!$A$2:$A$520,0)),"")} | D23: {=IFERROR(INDEX('노드'!$B$2:$B$520,MATCH(B23,'노드'!$A$2:$A$520,0)),"")}
A24: b6 | B24: b7 | C24: {=IFERROR(INDEX('노드'!$B$2:$B$520,MATCH(A24,'노드'!$A$2:$A$520,0)),"")} | D24: {=IFERROR(INDEX('노드'!$B$2:$B$520,MATCH(B24,'노드'!$A$2:$A$520,0)),"")}
A25: b4 | B25: b1 | C25: {=IFERROR(INDEX('노드'!$B$2:$B$520,MATCH(A25,'노드'!$A$2:$A$520,0)),"")} | D25: {=IFERROR(INDEX('노드'!$B$2:$B$520,MATCH(B25,'노드'!$A$2:$A$520,0)),"")}
A26: p1 | B26: p2 | C26: {=IFERROR(INDEX('노드'!$B$2:$B$520,MATCH(A26,'노드'!$A$2:$A$520,0)),"")} | D26: {=IFERROR(INDEX('노드'!$B$2:$B$520,MATCH(B26,'노드'!$A$2:$A$520,0)),"")} | E26: 대비 | F26: 문화적 기억은 소통적 기억과 짝을 이루는 개념입니다.
A27: p1 | B27: p3 | C27: {=IFERROR(INDEX('노드'!$B$2:$B$520,MATCH(A27,'노드'!$A$2:$A$520,0)),"")} | D27: {=IFERROR(INDEX('노드'!$B$2:$B$520,MATCH(B27,'노드'!$A$2:$A$520,0)),"")} | E27: 매체 | F27: 문화적 기억은 매체를 통해 세대를 넘어 유지됩니다.
A28: p1 | B28: p4 | C28: {=IFERROR(INDEX('노드'!$B$2:$B$520,MATCH(A28,'노드'!$A$2:$A$520,0)),"")} | D28: {=IFERROR(INDEX('노드'!$B$2:$B$520,MATCH(B28,'노드'!$A$2:$A$520,0)),"")} | E28: 공간 | F28: 기억은 장소와 공간에 의지해 유지됩니다.
A29: p5 | B29: p6 | C29: {=IFERROR(INDEX('노드'!$B$2:$B$520,MATCH(A29,'노드'!$A$2:$A$520,0)),"")} | D29: {=IFERROR(INDEX('노드'!$B$2:$B$520,MATCH(B29,'노드'!$A$2:$A$520,0)),"")} | E29: 개념 | F29: 알라이다 아스만은 저장기억과 기능기억을 구분합니다.
A30: p5 | B30: p7 | C30: {=IFERROR(INDEX('노드'!$B$2:$B$520,MATCH(A30,'노드'!$A$2:$A$520,0)),"")} | D30: {=IFERROR(INDEX('노드'!$B$2:$B$520,MATCH(B30,'노드'!$A$2:$A$520,0)),"")} | E30: 개념 | F30: 알라이다 아스만은 저장기억과 기능기억을 구분합니다.
A31: p1 | B31: p5 | C31: {=IFERROR(INDEX('노드'!$B$2:$B$520,MATCH(A31,'노드'!$A$2:$A$520,0)),"")} | D31: {=IFERROR(INDEX('노드'!$B$2:$B$520,MATCH(B31,'노드'!$A$2:$A$520,0)),"")}
A32: p7 | B32: b7 | C32: {=IFERROR(INDEX('노드'!$B$2:$B$520,MATCH(A32,'노드'!$A$2:$A$520,0)),"")} | D32: {=IFERROR(INDEX('노드'!$B$2:$B$520,MATCH(B32,'노드'!$A$2:$A$520,0)),"")}
A33: p7 | B33: a1 | C33: {=IFERROR(INDEX('노드'!$B$2:$B$520,MATCH(A33,'노드'!$A$2:$A$520,0)),"")} | D33: {=IFERROR(INDEX('노드'!$B$2:$B$520,MATCH(B33,'노드'!$A$2:$A$520,0)),"")} | E33: 기억의 정치 | F33: 학계가 만든 틀이 과거를 정리하는 기준이 된 사례입니다.
A34: p7 | B34: a2 | C34: {=IFERROR(INDEX('노드'!$B$2:$B$520,MATCH(A34,'노드'!$A$2:$A$520,0)),"")} | D34: {=IFERROR(INDEX('노드'!$B$2:$B$520,MATCH(B34,'노드'!$A$2:$A$520,0)),"")} | E34: 기억의 정치 | F34: 새 자료로 기존 틀이 교정된 과정입니다.
A35: p7 | B35: a5 | C35: {=IFERROR(INDEX('노드'!$B$2:$B$520,MATCH(A35,'노드'!$A$2:$A$520,0)),"")} | D35: {=IFERROR(INDEX('노드'!$B$2:$B$520,MATCH(B35,'노드'!$A$2:$A$520,0)),"")} | E35: 기억의 정치 | F35: 기원을 어떻게 볼지에 집단의 기억이 스며들 수 있는지 묻습니다.
A36: p6 | B36: b5 | C36: {=IFERROR(INDEX('노드'!$B$2:$B$520,MATCH(A36,'노드'!$A$2:$A$520,0)),"")} | D36: {=IFERROR(INDEX('노드'!$B$2:$B$520,MATCH(B36,'노드'!$A$2:$A$520,0)),"")}
A37: p2 | B37: b2 | C37: {=IFERROR(INDEX('노드'!$B$2:$B$520,MATCH(A37,'노드'!$A$2:$A$520,0)),"")} | D37: {=IFERROR(INDEX('노드'!$B$2:$B$520,MATCH(B37,'노드'!$A$2:$A$520,0)),"")}
A38: p8 | B38: p3 | C38: {=IFERROR(INDEX('노드'!$B$2:$B$520,MATCH(A38,'노드'!$A$2:$A$520,0)),"")} | D38: {=IFERROR(INDEX('노드'!$B$2:$B$520,MATCH(B38,'노드'!$A$2:$A$520,0)),"")} | E38: 매체 | F38: 전승이 끊긴 뒤에도 매체로서의 돌은 남습니다.
A39: p8 | B39: p7 | C39: {=IFERROR(INDEX('노드'!$B$2:$B$520,MATCH(A39,'노드'!$A$2:$A$520,0)),"")} | D39: {=IFERROR(INDEX('노드'!$B$2:$B$520,MATCH(B39,'노드'!$A$2:$A$520,0)),"")}
A40: p9 | B40: p6 | C40: {=IFERROR(INDEX('노드'!$B$2:$B$520,MATCH(A40,'노드'!$A$2:$A$520,0)),"")} | D40: {=IFERROR(INDEX('노드'!$B$2:$B$520,MATCH(B40,'노드'!$A$2:$A$520,0)),"")} | E40: 저장 | F40: 스캔 데이터는 새로운 방식의 저장입니다.
...

Sheet 분류
B1: 분류 이름 | C1: 색상코드
A2: c | B2: 고인돌 | C2: #f3dc94
A3: a | B3: 청동기시대 연구사 | C3: #6cc0e8
A4: b | B4: 고인돌 종합조사 | C4: #f0a46a
A5: p | B5: 철학적 사유 | C5: #b9a2f2
A6: u | B6: 세종 지역 고인돌 | C6: #8fd6a5
A7: k | B7: 금강 유역 고인돌 | C7: #1e73be
A8: e | B8: 스캔데이터 | C8: #4b6366
A9: n | B9: 명칭 | C9: #f7ca82
A10: d | B10: 거석문화 | C10: #815208
A11: w | B11: 세계의 고인돌 | C11: #FF7F00
A12: r | B12: 칠성바위 | C12: #82f047
A13: s | B13: 바위그림 | C13: #4b6366
A14: m | B14: 성혈 | C14: #fff3c4

Sheet 성혈
A1: 셩혈ID | B1: 직경(mm) | C1: 크기 등급 | D1: 깊이(mm) | E1: 깊이등급 | F1: 위치 (X위치,Y위치,Z위치) | G1: 비고
A2: C01 | B2: 80.3675 | C2: 1 | D2: 21.3874 | E2: 2 | F2: -292.941040,328.487183,-72.369949
A3: C02 | B3: 61.1358 | C3: 2 | D3: 12.7711 | E3: 3 | F3: -195.389369,350.596903,-30.890050
A4: C03 | B4: 52.0832 | C4: 3 | D4: 9.7793 | E4: 4 | F4: 123.254715,342.970062,-212.607346
A5: C04 | B5: 60.0184 | C5: 2 | D5: 23.8691 | E5: 2 | F5: 329.202515,335.423340,-316.891418
A6: C05 | B6: 43.696 | C6: 3 | D6: 13.0195 | E6: 3 | F6: -102.069679,357.611359,225.511978
A7: C06 | B7: 32.8949 | C7: 4 | D7: 8.8471 | E7: 4 | F7: -228.650345,356.427460,155.875198
A8: C07 | B8: 17.8671 | C8: 5 | D8: 4.5896 | E8: 5 | F8: -314.526611,357.206146,184.740692
A9: C08 | B9: 40.9433 | C9: 3 | D9: 16.9342 | E9: 3 | F9: -452.053406,295.734039,455.333832
A10: C09 | B10: 40.2115 | C10: 3 | D10: 15.9508 | E10: 3 | F10: -79.819710,317.816681,445.320709
A11: C10 | B11: 34.2068 | C11: 4 | D11: 20.1902 | E11: 2 | F11: -190.186737,288.035858,509.857300
A12: C11 | B12: 15.8728 | C12: 5 | D12: 8.0549 | E12: 4 | F12: -169.592651,329.602020,417.141998
A13: C12 | B13: 38.5589 | C13: 4 | D13: 7.802 | E13: 4 | F13: -402.091064,344.902313,248.274567
... A47: C46 | B47: 22.6665 | C47: 4 | D47: 11.0665 | E47: 3 | F47: -70.565826,347.532562,358.628204
